<?xml version="1.0" ?>
<!-- =================================================================================== -->
<!-- |    This document was autogenerated by xacro from bobik_robot.urdf.xacro         | -->
<!-- |    EDITING THIS FILE BY HAND IS NOT RECOMMENDED                                 | -->
<!-- =================================================================================== -->
<robot name="bobik">
  <material name="mat_wheel">
    <texture filename="package://bobik_robot/meshes/wheel.png"/>
  </material>
  <!-- Init colour -->
  <material name="black">
    <color rgba="0.0 0.0 0.0 1.0"/>
  </material>
  <material name="dark">
    <color rgba="0.3 0.3 0.3 1.0"/>
  </material>
  <material name="light_black">
    <color rgba="0.4 0.4 0.4 1.0"/>
  </material>
  <material name="blue">
    <color rgba="0.0 0.0 0.8 1.0"/>
  </material>
  <material name="green">
    <color rgba="0.0 0.8 0.0 1.0"/>
  </material>
  <material name="grey">
    <color rgba="0.5 0.5 0.5 1.0"/>
  </material>
  <material name="orange">
    <color rgba="1.0 0.4235294117647059 0.0392156862745098 1.0"/>
  </material>
  <material name="brown">
    <color rgba="0.8705882352941177 0.8117647058823529 0.7647058823529411 1.0"/>
  </material>
  <material name="red">
    <color rgba="0.8 0.0 0.0 1.0"/>
  </material>
  <material name="white">
    <color rgba="1.0 1.0 1.0 1.0"/>
  </material>
  <gazebo reference="base_link">
    <material>Gazebo/DarkGrey</material>
  </gazebo>
  <gazebo reference="lf_caster_rotation_link">
    <mu1>0.1</mu1>
    <mu2>0.1</mu2>
    <kp>500000.0</kp>
    <kd>10.0</kd>
    <minDepth>0.001</minDepth>
    <maxVel>0.1</maxVel>
    <fdir1>1 0 0</fdir1>
    <material>Gazebo/FlatBlack</material>
  </gazebo>
  <gazebo reference="lr_caster_rotation_link">
    <mu1>0.1</mu1>
    <mu2>0.1</mu2>
    <kp>500000.0</kp>
    <kd>10.0</kd>
    <minDepth>0.001</minDepth>
    <maxVel>0.1</maxVel>
    <fdir1>1 0 0</fdir1>
    <material>Gazebo/FlatBlack</material>
  </gazebo>
  <gazebo reference="r_caster_rotation_link">
    <mu1>0.1</mu1>
    <mu2>0.1</mu2>
    <kp>1000000.0</kp>
    <kd>100.0</kd>
    <minDepth>0.001</minDepth>
    <maxVel>1.0</maxVel>
    <material>Gazebo/FlatBlack</material>
  </gazebo>
  <gazebo reference="imu_link">
    <sensor name="imu" type="imu">
      <always_on>true</always_on>
      <visualize>false</visualize>
    </sensor>
    <material>Gazebo/FlatBlack</material>
  </gazebo>
  <gazebo>
    <plugin filename="libgazebo_ros_diff_drive.so" name="turtlebot3_burger_controller">
      <commandTopic>cmd_vel</commandTopic>
      <odometryTopic>odom</odometryTopic>
      <odometryFrame>odom</odometryFrame>
      <odometrySource>world</odometrySource>
      <publishOdomTF>true</publishOdomTF>
      <robotBaseFrame>base_footprint</robotBaseFrame>
      <publishWheelTF>false</publishWheelTF>
      <publishTf>true</publishTf>
      <publishWheelJointState>true</publishWheelJointState>
      <legacyMode>false</legacyMode>
      <updateRate>20</updateRate>
      <leftJoint>lf_caster_rotation_link</leftJoint>
      <rightJoint>rf_caster_rotation_link</rightJoint>
      <wheelSeparation>0.46</wheelSeparation>
      <wheelDiameter>0.123</wheelDiameter>
      <wheelAcceleration>1</wheelAcceleration>
      <wheelTorque>10</wheelTorque>
      <rosDebugLevel>na</rosDebugLevel>
    </plugin>
  </gazebo>
  <gazebo>
    <plugin filename="libgazebo_ros_imu.so" name="imu_plugin">
      <alwaysOn>true</alwaysOn>
      <bodyName>imu_link</bodyName>
      <frameName>imu_link</frameName>
      <topicName>imu</topicName>
      <serviceName>imu_service</serviceName>
      <gaussianNoise>0.0</gaussianNoise>
      <updateRate>0</updateRate>
      <imu>
        <noise>
          <type>gaussian</type>
          <rate>
            <mean>0.0</mean>
            <stddev>2e-4</stddev>
            <bias_mean>0.0000075</bias_mean>
            <bias_stddev>0.0000008</bias_stddev>
          </rate>
          <accel>
            <mean>0.0</mean>
            <stddev>1.7e-2</stddev>
            <bias_mean>0.1</bias_mean>
            <bias_stddev>0.001</bias_stddev>
          </accel>
        </noise>
      </imu>
    </plugin>
  </gazebo>
  <gazebo reference="base_scan">
    <material>Gazebo/FlatBlack</material>
    <sensor name="lds_lfcd_sensor" type="ray">
      <pose>0 0 0 0 0 0</pose>
      <visualize>false</visualize>
      <update_rate>5</update_rate>
      <ray>
        <scan>
          <horizontal>
            <samples>360</samples>
            <resolution>1</resolution>
            <min_angle>0.0</min_angle>
            <max_angle>6.28319</max_angle>
          </horizontal>
        </scan>
        <range>
          <min>0.120</min>
          <max>3.5</max>
          <resolution>0.015</resolution>
        </range>
        <noise>
          <type>gaussian</type>
          <mean>0.0</mean>
          <stddev>0.01</stddev>
        </noise>
      </ray>
      <plugin filename="libgazebo_ros_laser.so" name="gazebo_ros_lds_lfcd_controller">
        <topicName>scan</topicName>
        <frameName>base_scan</frameName>
      </plugin>
    </sensor>
  </gazebo>
  <!-- root_link is a workaround for base_link to have an inertia mass -->
  <link name="base_footprint"/>
  <joint name="root_joint" type="fixed">
    <parent link="base_footprint"/>
    <child link="base_link"/>
  </joint>
  <link name="base_link">
    <visual>
      <origin rpy="0 0 0" xyz="0 0 0"/>
      <geometry>
        <mesh filename="file:///home/honza/ros2_foxy/src/bobik_robot/meshes/base_link.dae"/>
      </geometry>
    </visual>
    <collision>
      <origin rpy="0 0 0" xyz="0 0 0"/>
      <geometry>
        <mesh filename="file:///home/honza/ros2_foxy/src/bobik_robot/meshes/base_link_collision.dae"/>
      </geometry>
    </collision>
    <inertial>
      <origin rpy="0 0 0" xyz="0 0 0"/>
      <mass value="1.5"/>
      <inertia ixx="2.2124416e-03" ixy="-1.2294101e-05" ixz="3.4938785e-05" iyy="2.1193702e-03" iyz="-5.0120904e-06" izz="2.0064271e-03"/>
    </inertial>
  </link>
  <joint name="fl_caster_rotation_joint" type="revolute">
    <parent link="base_link"/>
    <child link="fl_caster_rotation_link"/>
    <origin rpy="0 0 0.0" xyz="0.134 0.23 0.173"/>
    <axis xyz="0 0 1"/>
    <limit effort="20" lower="-1.5707963267948966" upper="1.5707963267948966" velocity="3.141592653589793"/>
  </joint>
  <link name="fl_caster_rotation_link">
    <visual>
      <origin rpy="0 0 0" xyz="0 0 0"/>
      <geometry>
        <mesh filename="package://bobik_robot/meshes/caster_rotation_link.dae"/>
      </geometry>
    </visual>
    <collision>
      <origin rpy="0 0 0" xyz="0 0 0"/>
      <geometry>
        <box size="0.08 0.075 0.11"/>
      </geometry>
    </collision>
    <inertial>
      <origin rpy="0 0 0" xyz="-0.04 -0.026 -0.025"/>
      <mass value="0.5"/>
      <inertia ixx="2.2124416e-03" ixy="-1.2294101e-05" ixz="3.4938785e-05" iyy="2.1193702e-03" iyz="-5.0120904e-06" izz="2.0064271e-03"/>
    </inertial>
  </link>
  <joint name="fl_caster_wheel_joint" type="continuous">
    <parent link="fl_caster_rotation_link"/>
    <child link="fl_caster_wheel_link"/>
    <origin rpy="0 0 0" xyz="0 0 -0.110"/>
    <axis xyz="0 1 0"/>
    <limit effort="30" velocity="6.283185307179586"/>
  </joint>
  <link name="fl_caster_wheel_link">
    <visual>
      <origin rpy="1.5707963267948966 0 0" xyz="0 0 0"/>
      <geometry>
        <cylinder length="0.024" radius="0.0615"/>
      </geometry>
      <material name="mat_wheel"/>
    </visual>
    <collision>
      <origin rpy="0 0 0" xyz="0 0 0"/>
      <geometry>
        <box size="0.123 0.024 0.123"/>
      </geometry>
    </collision>
    <inertial>
      <origin rpy="0 0 0" xyz="0 0 0"/>
      <mass value="0.15"/>
      <inertia ixx="2.2124416e-03" ixy="-1.2294101e-05" ixz="3.4938785e-05" iyy="2.1193702e-03" iyz="-5.0120904e-06" izz="2.0064271e-03"/>
    </inertial>
  </link>
  <joint name="fr_caster_rotation_joint" type="revolute">
    <parent link="base_link"/>
    <child link="fr_caster_rotation_link"/>
    <origin rpy="0 0 0.0" xyz="0.134 -0.23 0.173"/>
    <axis xyz="0 0 1"/>
    <limit effort="20" lower="-1.5707963267948966" upper="1.5707963267948966" velocity="3.141592653589793"/>
  </joint>
  <link name="fr_caster_rotation_link">
    <visual>
      <origin rpy="0 0 0" xyz="0 0 0"/>
      <geometry>
        <mesh filename="package://bobik_robot/meshes/caster_rotation_link.dae"/>
      </geometry>
    </visual>
    <collision>
      <origin rpy="0 0 0" xyz="0 0 0"/>
      <geometry>
        <box size="0.08 0.075 0.11"/>
      </geometry>
    </collision>
    <inertial>
      <origin rpy="0 0 0" xyz="-0.04 -0.026 -0.025"/>
      <mass value="0.5"/>
      <inertia ixx="2.2124416e-03" ixy="-1.2294101e-05" ixz="3.4938785e-05" iyy="2.1193702e-03" iyz="-5.0120904e-06" izz="2.0064271e-03"/>
    </inertial>
  </link>
  <joint name="fr_caster_wheel_joint" type="continuous">
    <parent link="fr_caster_rotation_link"/>
    <child link="fr_caster_wheel_link"/>
    <origin rpy="0 0 0" xyz="0 0 -0.110"/>
    <axis xyz="0 1 0"/>
    <limit effort="30" velocity="6.283185307179586"/>
  </joint>
  <link name="fr_caster_wheel_link">
    <visual>
      <origin rpy="1.5707963267948966 0 0" xyz="0 0 0"/>
      <geometry>
        <cylinder length="0.024" radius="0.0615"/>
      </geometry>
      <material name="mat_wheel"/>
    </visual>
    <collision>
      <origin rpy="0 0 0" xyz="0 0 0"/>
      <geometry>
        <box size="0.123 0.024 0.123"/>
      </geometry>
    </collision>
    <inertial>
      <origin rpy="0 0 0" xyz="0 0 0"/>
      <mass value="0.15"/>
      <inertia ixx="2.2124416e-03" ixy="-1.2294101e-05" ixz="3.4938785e-05" iyy="2.1193702e-03" iyz="-5.0120904e-06" izz="2.0064271e-03"/>
    </inertial>
  </link>
  <joint name="r_caster_rotation_joint" type="revolute">
    <parent link="base_link"/>
    <child link="r_caster_rotation_link"/>
    <origin rpy="0 0 0.0" xyz="-0.270 0.0 0.173"/>
    <axis xyz="0 0 1"/>
    <limit effort="20" lower="-1.5707963267948966" upper="1.5707963267948966" velocity="3.141592653589793"/>
  </joint>
  <link name="r_caster_rotation_link">
    <visual>
      <origin rpy="0 0 0" xyz="0 0 0"/>
      <geometry>
        <mesh filename="package://bobik_robot/meshes/caster_rotation_link.dae"/>
      </geometry>
    </visual>
    <collision>
      <origin rpy="0 0 0" xyz="0 0 0"/>
      <geometry>
        <box size="0.08 0.075 0.11"/>
      </geometry>
    </collision>
    <inertial>
      <origin rpy="0 0 0" xyz="-0.04 -0.026 -0.025"/>
      <mass value="0.5"/>
      <inertia ixx="2.2124416e-03" ixy="-1.2294101e-05" ixz="3.4938785e-05" iyy="2.1193702e-03" iyz="-5.0120904e-06" izz="2.0064271e-03"/>
    </inertial>
  </link>
  <joint name="r_caster_wheel_joint" type="continuous">
    <parent link="r_caster_rotation_link"/>
    <child link="r_caster_wheel_link"/>
    <origin rpy="0 0 0" xyz="0 0 -0.110"/>
    <axis xyz="0 1 0"/>
    <limit effort="30" velocity="6.283185307179586"/>
  </joint>
  <link name="r_caster_wheel_link">
    <visual>
      <origin rpy="1.5707963267948966 0 0" xyz="0 0 0"/>
      <geometry>
        <cylinder length="0.024" radius="0.0615"/>
      </geometry>
      <material name="mat_wheel"/>
    </visual>
    <collision>
      <origin rpy="0 0 0" xyz="0 0 0"/>
      <geometry>
        <box size="0.123 0.024 0.123"/>
      </geometry>
    </collision>
    <inertial>
      <origin rpy="0 0 0" xyz="0 0 0"/>
      <mass value="0.15"/>
      <inertia ixx="2.2124416e-03" ixy="-1.2294101e-05" ixz="3.4938785e-05" iyy="2.1193702e-03" iyz="-5.0120904e-06" izz="2.0064271e-03"/>
    </inertial>
  </link>
  <joint name="lidar_joint" type="fixed">
    <parent link="base_link"/>
    <child link="lidar_link"/>
  </joint>
  <link name="lidar_link">
    <visual>
      <origin rpy="0 0 0" xyz="0.12 0.13 0.23249999999999998"/>
      <geometry>
        <cylinder length="0.018" radius="0.04"/>
      </geometry>
      <material name="black"/>
    </visual>
    <collision>
      <origin rpy="0 0 0" xyz="0 0 0"/>
      <geometry>
        <box size="0.08 0.08 0.045"/>
      </geometry>
    </collision>
    <inertial>
      <origin rpy="0 0 0" xyz="0 0 0"/>
      <mass value="0.2"/>
      <inertia ixx="2.2124416e-04" ixy="-1.2294101e-06" ixz="3.4938785e-06" iyy="2.1193702e-04" iyz="-5.0120904e-05" izz="2.0064271e-04"/>
    </inertial>
  </link>
</robot>
